Workbook
Name Slicer_Gender: #N/A
Name Slicer_Occupation: #N/A
Name Slicer_OrderStatus: #N/A
Name Slicer_PaymentMode: #N/A
Name Slicer_StoreType: #N/A

Sheet Orders
A1: OrderID | B1: CustomerID | C1: ProductID | D1: OrderDate | E1: Quantity | F1: UnitPrice | G1: TotalAmount | H1: DiscountApplied | I1: PaymentMode | J1: OrderStatus | K1: DeliveryDate | L1: IsGift | M1: ShippingCharges | N1: CouponUsed | O1: ReviewGiven
A2: O1001 | B2: C085 | C2: P180 | D2: 45687 | E2: 5 | F2: 31647 | G2: 94941 | H2: 0.14 | I2: Cash on Delivery | J2: Delivered | K2: 45859 | L2: Yes | M2: 41 | N2: Yes | O2: No
A3: O1002 | B3: C084 | C3: P127 | D3: 45802 | E3: 5 | F3: 24100 | G3: 96400 | H3: 0.1 | I3: Cash on Delivery | J3: Delivered | K3: 45858 | L3: No | M3: 455 | N3: No | O3: No
A4: O1003 | B4: C062 | C4: P132 | D4: 45697 | E4: 4 | F4: 89335 | G4: 268005 | H4: 0.29 | I4: Net Banking | J4: Delivered | K4: 45862 | L4: Yes | M4: 80 | N4: No | O4: No
A5: O1004 | B5: C062 | C5: P160 | D5: 45640 | E5: 2 | F5: 90888 | G5: 272664 | H5: 0.16 | I5: Cash on Delivery | J5: Shipped | K5: 45869 | L5: No | M5: 441 | N5: No | O5: No
A6: O1005 | B6: C052 | C6: P117 | D6: 45735 | E6: 3 | F6: 72884 | G6: 364420 | H6: 0.18 | I6: Cash on Delivery | J6: Delivered | K6: 45856 | L6: No | M6: 123 | N6: No | O6: Yes
A7: O1006 | B7: C035 | C7: P158 | D7: 45609 | E7: 2 | F7: 92731 | G7: 185462 | H7: 0.12 | I7: Credit Card | J7: Delivered | K7: 45865 | L7: No | M7: 484 | N7: No | O7: No
A8: O1007 | B8: C032 | C8: P121 | D8: 45772 | E8: 3 | F8: 25227 | G8: 126135 | H8: 0.27 | I8: UPI | J8: Shipped | K8: 45860 | L8: Yes | M8: 255 | N8: No | O8: No
A9: O1008 | B9: C040 | C9: P164 | D9: 45511 | E9: 1 | F9: 61962 | G9: 61962 | H9: 0.19 | I9: Net Banking | J9: Cancelled | K9: 45860 | L9: Yes | M9: 110 | N9: No | O9: Yes
A10: O1009 | B10: C007 | C10: P137 | D10: 45522 | E10: 4 | F10: 6443 | G10: 32215 | H10: 0.06 | I10: Net Banking | J10: Pending | K10: 45865 | L10: Yes | M10: 433 | N10: Yes | O10: No
A11: O1010 | B11: C018 | C11: P134 | D11: 45534 | E11: 3 | F11: 63656 | G11: 254624 | H11: 0.3 | I11: UPI | J11: Delivered | K11: 45866 | L11: No | M11: 26 | N11: Yes | O11: No
A12: O1011 | B12: C071 | C12: P137 | D12: 45726 | E12: 1 | F12: 6443 | G12: 25772 | H12: 0.06 | I12: Cash on Delivery | J12: Cancelled | K12: 45869 | L12: No | M12: 422 | N12: Yes | O12: Yes
A13: O1012 | B13: C013 | C13: P151 | D13: 45510 | E13: 3 | F13: 46390 | G13: 139170 | H13: 0.22 | I13: Cash on Delivery | J13: Pending | K13: 45862 | L13: Yes | M13: 101 | N13: No | O13: Yes
... A84: O1083 | B84: C051 | C84: P147 | D84: 45525 | E84: 1 | F84: 72764 | G84: 363820 | H84: 0.28 | I84: Debit Card | J84: Shipped | K84: 45856 | L84: Yes | M84: 487 | N84: No | O84: Yes
A85: O1084 | B85: C057 | C85: P138 | D85: 45846 | E85: 1 | F85: 97904 | G85: 391616 | H85: 0.27 | I85: Net Banking | J85: Shipped | K85: 45860 | L85: No | M85: 123 | N85: No | O85: Yes | V85: 100
A86: O1085 | B86: C092 | C86: P155 | D86: 45837 | E86: 4 | F86: 56076 | G86: 56076 | H86: 0.2 | I86: Net Banking | J86: Cancelled | K86: 45867 | L86: No | M86: 273 | N86: No | O86: Yes
A87: O1086 | B87: C047 | C87: P190 | D87: 45649 | E87: 5 | F87: 10335 | G87: 51675 | H87: 0.26 | I87: Credit Card | J87: Delivered | K87: 45864 | L87: Yes | M87: 336 | N87: No | O87: Yes
A88: O1087 | B88: C083 | C88: P179 | D88: 45667 | E88: 1 | F88: 59299 | G88: 296495 | H88: 0.24 | I88: Net Banking | J88: Pending | K88: 45857 | L88: No | M88: 54 | N88: Yes | O88: Yes
A89: O1088 | B89: C034 | C89: P129 | D89: 45714 | E89: 5 | F89: 39710 | G89: 198550 | H89: 0.25 | I89: Cash on Delivery | J89: Shipped | K89: 45857 | L89: No | M89: 191 | N89: No | O89: No
A90: O1089 | B90: C099 | C90: P187 | D90: 45685 | E90: 5 | F90: 52931 | G90: 264655 | H90: 0.28 | I90: Debit Card | J90: Pending | K90: 45858 | L90: Yes | M90: 247 | N90: Yes | O90: No
A91: O1090 | B91: C054 | C91: P111 | D91: 45736 | E91: 1 | F91: 90766 | G91: 181532 | H91: 0.14 | I91: UPI | J91: Pending | K91: 45864 | L91: No | M91: 233 | N91: Yes | O91: No
A92: O1091 | B92: C045 | C92: P161 | D92: 45518 | E92: 1 | F92: 98254 | G92: 393016 | H92: 0.15 | I92: Net Banking | J92: Pending | K92: 45869 | L92: Yes | M92: 153 | N92: Yes | O92: Yes
A93: O1092 | B93: C003 | C93: P144 | D93: 45709 | E93: 1 | F93: 29538 | G93: 59076 | H93: 0.24 | I93: Debit Card | J93: Shipped | K93: 45856 | L93: Yes | M93: 169 | N93: No | O93: No
A94: O1093 | B94: C030 | C94: P152 | D94: 45657 | E94: 2 | F94: 92604 | G94: 185208 | H94: 0.29 | I94: Net Banking | J94: Cancelled | K94: 45858 | L94: Yes | M94: 377 | N94: Yes | O94: No
A95: O1094 | B95: C076 | C95: P155 | D95: 45580 | E95: 4 | F95: 56076 | G95: 56076 | H95: 0.2 | I95: Debit Card | J95: Shipped | K95: 45862 | L95: No | M95: 385 | N95: Yes | O95: Yes
A96: O1095 | B96: C069 | C96: P124 | D96: 45590 | E96: 3 | F96: 43565 | G96: 130695 | H96: 0.26 | I96: Debit Card | J96: Cancelled | K96: 45862 | L96: Yes | M96: 134 | N96: No | O96: No
A97: O1096 | B97: C077 | C97: P150 | D97: 45848 | E97: 5 | F97: 98841 | G97: 395364 | H97: 0.18 | I97: Cash on Delivery | J97: Delivered | K97: 45864 | L97: No | M97: 180 | N97: No | O97: Yes
... A101: O1100 | B101: C041 | C101: P158 | D101: 45518 | E101: 5 | F101: 92731 | G101: 92731 | H101: 0.12 | I101: UPI | J101: Delivered | K101: 45859 | L101: No | M101: 69 | N101: Yes | O101: No

Sheet Products
A1: ProductID | B1: ProductName | C1: Category | D1: SubCategory | E1: Brand | F1: Price | G1: Discount | H1: StockQty | I1: WarrantyMonths | J1: MadeIn | K1: IsAvailable | L1: Rating | M1: LaunchDate | N1: Returnable | O1: HSNCode | P1: Store ID
A2: P101 | B2: At Rice | C2: Grocery | D2: Organic | E2: Saran LLC | F2: 45556 | G2: 18 | H2: 763 | I2: 24 | J2: Vietnam | K2: No | L2: 3.2 | M2: 45413 | N2: No | O2: 4778 | P2: 55
A3: P102 | B3: In Laptop | C3: Electronics | D3: Smart | E3: Bose-Patel | F3: 41859 | G3: 8 | H3: 760 | I3: 12 | J3: China | K3: Yes | L3: 4.3 | M3: 45150 | N3: No | O3: 9596 | P3: 72
A4: P103 | B4: Expedita TV | C4: Fashion | D4: Smart | E4: Tandon, Hayre and Shankar | F4: 39329 | G4: 12 | H4: 369 | I4: 12 | J4: Vietnam | K4: Yes | L4: 4.3 | M4: 44925 | N4: Yes | O4: 5495 | P4: 42
A5: P104 | B5: Deleniti TV | C5: Electronics | D5: Organic | E5: Ahuja-Randhawa | F5: 38790 | G5: 27 | H5: 966 | I5: 12 | J5: Japan | K5: Yes | L5: 4.7 | M5: 45275 | N5: No | O5: 8691 | P5: 47
A6: P105 | B6: Sit Washing Machine | C6: Grocery | D6: Cotton | E6: Narayan-Sarraf | F6: 24664 | G6: 6 | H6: 258 | I6: 36 | J6: India | K6: Yes | L6: 3.5 | M6: 45278 | N6: Yes | O6: 1879 | P6: 145
A7: P106 | B7: Non Shirt | C7: Home Appliance | D7: Organic | E7: Deshpande, Mital and Nagi | F7: 40324 | G7: 7 | H7: 254 | I7: 6 | J7: Japan | K7: Yes | L7: 4.4 | M7: 45696 | N7: No | O7: 8382 | P7: 104
A8: P107 | B8: Voluptate Phone | C8: Grocery | D8: Organic | E8: Srinivas LLC | F8: 56707 | G8: 14 | H8: 582 | I8: 6 | J8: India | K8: Yes | L8: 4.1 | M8: 45034 | N8: No | O8: 2331 | P8: 15
A9: P108 | B9: Nam Shirt | C9: Home Appliance | D9: Smart | E9: Manne-Swaminathan | F9: 72850 | G9: 7 | H9: 160 | I9: 6 | J9: Japan | K9: No | L9: 4.2 | M9: 45653 | N9: No | O9: 5772 | P9: 87
A10: P109 | B10: Exercitationem Shirt | C10: Electronics | D10: Cotton | E10: Puri-Mand | F10: 93162 | G10: 14 | H10: 719 | I10: 36 | J10: India | K10: Yes | L10: 4.8 | M10: 45369 | N10: Yes | O10: 7966 | P10: 44
A11: P110 | B11: Maiores Rice | C11: Electronics | D11: Smart | E11: Iyengar PLC | F11: 85386 | G11: 9 | H11: 930 | I11: 24 | J11: China | K11: Yes | L11: 2.6 | M11: 45606 | N11: No | O11: 5729 | P11: 92
A12: P111 | B12: Ducimus TV | C12: Grocery | D12: Android | E12: Bala, Shenoy and Kadakia | F12: 90766 | G12: 14 | H12: 716 | I12: 36 | J12: Vietnam | K12: No | L12: 3.6 | M12: 45440 | N12: Yes | O12: 8079 | P12: 71
A13: P112 | B13: Illum Rice | C13: Fashion | D13: Cotton | E13: Biswas, Rege and Tata | F13: 3890 | G13: 7 | H13: 234 | I13: 6 | J13: Vietnam | K13: Yes | L13: 4.4 | M13: 44975 | N13: Yes | O13: 8709 | P13: 50
... A101: P200 | B101: Dolor Shirt | C101: Fashion | D101: Notebook | E101: Chacko-Mukherjee | F101: 72699 | G101: 13 | H101: 128 | I101: 24 | J101: India | K101: Yes | L101: 4 | M101: 44881 | N101: Yes | O101: 3805 | P101: 186

Sheet customers
A1: CustomerID | B1: CustomerName | C1: Email | D1: Phone | E1: City | F1: State | G1: Pincode | H1: Gender | I1: DateOfBirth | J1: CustomerSince | K1: PreferredCategory | L1: LoyaltyPoints | M1: MaritalStatus | N1: Occupation | O1: AnnualIncome
A2: C001 | B2: Aryan Maharaj | C2: udantdewan@example.net | D2: 918196001338 | E2: Mumbai | F2: Maharashtra | G2: 838637 | H2: Male | I2: 36394 | J2: 44892 | K2: Fashion | L2: 4112 | M2: Single | N2: Doctor | O2: 1744492
A3: C002 | B3: Nathaniel Sami | C3: arunima23@example.com | D3: 911615594078 | E3: Mumbai | F3: Maharashtra | G3: 618495 | H3: Male | I3: 36098 | J3: 44625 | K3: Grocery | L3: 620 | M3: Single | N3: Engineer | O3: 658517
A4: C003 | B4: Chakradev Kari | C4: fariq31@example.com | D4: 7525534192 | E4: Hyderabad | F4: Telangana | G4: 276483 | H4: Male | I4: 38764 | J4: 45035 | K4: Home Appliance | L4: 9028 | M4: Married | N4: Doctor | O4: 1142059
A5: C004 | B5: Veer Balay | C5: nandini41@example.org | D5: 5376724238 | E5: Lucknow | F5: Uttar Pradesh | G5: 969653 | H5: Female | I5: 25186 | J5: 45611 | K5: Electronics | L5: 2715 | M5: Married | N5: Teacher | O5: 782738
A6: C005 | B6: Gavin Batta | C6: duanathaniel@example.net | D6: 9166978480 | E6: Bangalore | F6: Karnataka | G6: 845146 | H6: Male | I6: 25679 | J6: 45437 | K6: Fashion | L6: 1774 | M6: Single | N6: Business | O6: 402828
A7: C006 | B7: Adya Tella | C7: yashicacherian@example.net | D7: 8932528809 | E7: Kolkata | F7: West Bengal | G7: 701543 | H7: Female | I7: 23187 | J7: 44776 | K7: Fashion | L7: 811 | M7: Married | N7: Student | O7: 461779
A8: C007 | B8: Frederick Sunder | C8: waliajeremiah@example.org | D8: 7824896383 | E8: Jaipur | F8: Rajasthan | G8: 657871 | H8: Male | I8: 27909 | J8: 44726 | K8: Fashion | L8: 6025 | M8: Single | N8: Engineer | O8: 296100
A9: C008 | B9: Hamsini Bail | C9: thomasamble@example.org | D9: 310518347 | E9: Hyderabad | F9: Telangana | G9: 829973 | H9: Female | I9: 33503 | J9: 45292 | K9: Electronics | L9: 3914 | M9: Single | N9: Business | O9: 782952
A10: C009 | B10: Girindra Chatterjee | C10: bpandya@example.com | D10: 106513338 | E10: Ahmedabad | F10: Gujarat | G10: 262473 | H10: Female | I10: 23621 | J10: 45404 | K10: Home Appliance | L10: 6165 | M10: Married | N10: Doctor | O10: 1605459
A11: C010 | B11: Chandresh Zachariah | C11: chanderwarjas@example.org | D11: 7736026064 | E11: Chennai | F11: Tamil Nadu | G11: 468723 | H11: Male | I11: 29122 | J11: 44704 | K11: Home Appliance | L11: 8851 | M11: Single | N11: Doctor | O11: 1169429
A12: C011 | B12: Darsh Murthy | C12: bedivansha@example.net | D12: 2081219136 | E12: Jaipur | F12: Rajasthan | G12: 939909 | H12: Female | I12: 23785 | J12: 45330 | K12: Home Appliance | L12: 5413 | M12: Single | N12: Doctor | O12: 1923444
A13: C012 | B13: Advika Jayaraman | C13: william46@example.org | D13: 4751079911 | E13: Delhi | F13: Delhi | G13: 842513 | H13: Female | I13: 30932 | J13: 44913 | K13: Grocery | L13: 4486 | M13: Single | N13: Doctor | O13: 1389462
... A101: C100 | B101: Harshil Bal | C101: pandyagirik@example.net | D101: 5604661839 | E101: Chennai | F101: Tamil Nadu | G101: 622444 | H101: Male | I101: 34004 | J101: 44481 | K101: Grocery | L101: 4086 | M101: Married | N101: Student | O101: 973891

Sheet stores
A1: New StoreID | B1: StoreID | C1: StoreName | D1: City | E1: State | F1: Pincode | G1: Manager | H1: EstablishedYear | I1: Employees | J1: MonthlyFootfall | K1: StoreRating | L1: OnlineEnabled | M1: AreaSqFt | N1: StoreType | O1: ContactNumber | P1: Email
A2: 1 | B2: S001 | C2: Chopra and Sons Mart | D2: Pune | E2: Maharashtra | F2: 277561 | G2: Sarthak Seth | H2: 2016 | I2: 88 | J2: 17219 | K2: 3.8 | L2: No | M2: 3904 | N2: Outlet | O2: 7411249035 | P2: gavinkothari@randhawa-varghese.com
A3: 2 | B3: S002 | C3: Mistry, Lad and Ghosh Mart | D3: Ahmedabad | E3: Gujarat | F3: 678831 | G3: Harsh Dey | H3: 2015 | I3: 26 | J3: 3708 | K3: 4.1 | L3: Yes | M3: 2892 | N3: Retail | O3: 910032365199 | P3: falan01@sawhney.com
A4: 3 | B4: S003 | C4: Das-Basak Mart | D4: Chennai | E4: Tamil Nadu | F4: 29667 | G4: Lavanya Sandhu | H4: 2007 | I4: 73 | J4: 10459 | K4: 3.3 | L4: No | M4: 4557 | N4: Outlet | O4: 915324472099 | P4: chakrikatara@srinivas-bhat.com
A5: 4 | B5: S004 | C5: Rajagopal-Devan Mart | D5: Pune | E5: Maharashtra | F5: 383806 | G5: Varsha Sundaram | H5: 2003 | I5: 78 | J5: 4742 | K5: 3.5 | L5: No | M5: 4940 | N5: Retail | O5: 9856420593 | P5: manddalbir@wagle-parmar.org
A6: 5 | B6: S005 | C6: Dutta Inc Mart | D6: Ahmedabad | E6: Gujarat | F6: 348039 | G6: Isha Ghose | H6: 2017 | I6: 32 | J6: 14931 | K6: 3.2 | L6: Yes | M6: 2938 | N6: Retail | O6: 913955905992 | P6: waidamore@swaminathan.com
A7: 6 | B7: S006 | C7: Kaul PLC Mart | D7: Ahmedabad | E7: Gujarat | F7: 87059 | G7: Kalpit Oak | H7: 2008 | I7: 49 | J7: 3850 | K7: 3.9 | L7: Yes | M7: 2441 | N7: Retail | O7: 2500292185 | P7: prakashmeghana@chaudhuri.com
A8: 7 | B8: S007 | C8: Dugar Ltd Mart | D8: Lucknow | E8: Uttar Pradesh | F8: 752895 | G8: Parth Radhakrishnan | H8: 2022 | I8: 49 | J8: 15030 | K8: 3.3 | L8: Yes | M8: 2192 | N8: Retail | O8: 4220969029 | P8: timothy91@dhaliwal-narula.com
A9: 8 | B9: S008 | C9: Palan LLC Mart | D9: Delhi | E9: Delhi | F9: 157043 | G9: Ekansh Palla | H9: 2018 | I9: 49 | J9: 18441 | K9: 3.6 | L9: Yes | M9: 3151 | N9: Outlet | O9: 1006762676 | P9: keya17@kar.com
A10: 9 | B10: S009 | C10: Menon Inc Mart | D10: Chennai | E10: Tamil Nadu | F10: 411526 | G10: Falan Chander | H10: 2009 | I10: 78 | J10: 9760 | K10: 4.9 | L10: Yes | M10: 1610 | N10: Franchise | O10: 9970629620 | P10: narulasamesh@rout.net
A11: 10 | B11: S010 | C11: Zachariah, Lanka and Manda Mart | D11: Delhi | E11: Delhi | F11: 310698 | G11: Mitesh Bhagat | H11: 2008 | I11: 88 | J11: 5157 | K11: 4.4 | L11: Yes | M11: 2545 | N11: Retail | O11: 614973103 | P11: bishakhabumb@dalia-morar.biz
A12: 11 | B12: S011 | C12: Suresh-Lanka Mart | D12: Kolkata | E12: West Bengal | F12: 862565 | G12: Sanaya Basu | H12: 2007 | I12: 91 | J12: 13868 | K12: 4 | L12: No | M12: 3893 | N12: Franchise | O12: 7743490211 | P12: odika93@bhat.biz
A13: 12 | B13: S012 | C13: Soman, Keer and Soni Mart | D13: Ahmedabad | E13: Gujarat | F13: 160898 | G13: Jai Sen | H13: 2002 | I13: 86 | J13: 4050 | K13: 3.8 | L13: No | M13: 3523 | N13: Franchise | O13: 912332061632 | P13: ekaja11@ranganathan-nanda.com
... A101: 100 | B101: S100 | C101: Kanda-Mander Mart | D101: Mumbai | E101: Maharashtra | F101: 300910 | G101: Jairaj Dar | H101: 2002 | I101: 54 | J101: 19230 | K101: 3.8 | L101: No | M101: 2762 | N101: Outlet | O101: 919269212447 | P101: settyaradhana@naik-kurian.com

Sheet All columns & ERD
A1: SNO | B1: Orders Columns | D1: SNO | E1: Customers Columns | G1: SNO | H1: Products Columns | K1: SNO | L1: Stores Columns | Q1: Orders Columns | R1: Customers Columns | S1: Products Columns | T1: Stores Columns
A2: {=_xlfn.SEQUENCE(COUNTA(B:B)-1,1,1,1)} -> 1 | B2: {=TRANSPOSE(orders[#Headers])} -> OrderID | D2: {=_xlfn.SEQUENCE(COUNTA(E:E)-1,1,1,1)} -> 1 | E2: {=TRANSPOSE(customers[#Headers])} -> CustomerID | G2: {=_xlfn.SEQUENCE(COUNTA(H:H)-1,1,1,1)} -> 1 | H2: {=TRANSPOSE(Products[#Headers])} -> ProductID | K2: {=_xlfn.SEQUENCE(COUNTA(L:L)-1,1,1,1)} -> 1 | L2: {=TRANSPOSE(stores[#Headers])} -> New StoreID | Q2: OrderID | R2: CustomerID | S2: ProductID | T2: StoreID
A3: 2 | B3: CustomerID | D3: 2 | E3: CustomerName | G3: 2 | H3: ProductName | K3: 2 | L3: StoreID | Q3: CustomerID | R3: CustomerName | S3: ProductName | T3: StoreName
A4: 3 | B4: ProductID | D4: 3 | E4: Email | G4: 3 | H4: Category | K4: 3 | L4: StoreName | Q4: ProductID | R4: Email | S4: Category | T4: City
A5: 4 | B5: OrderDate | D5: 4 | E5: Phone | G5: 4 | H5: SubCategory | K5: 4 | L5: City | Q5: OrderDate | R5: Phone | S5: SubCategory | T5: State
A6: 5 | B6: Quantity | D6: 5 | E6: City | G6: 5 | H6: Brand | K6: 5 | L6: State | Q6: Quantity | R6: City | S6: Brand | T6: Pincode
A7: 6 | B7: UnitPrice | D7: 6 | E7: State | G7: 6 | H7: Price | K7: 6 | L7: Pincode | Q7: UnitPrice | R7: State | S7: Price | T7: Manager
A8: 7 | B8: TotalAmount | D8: 7 | E8: Pincode | G8: 7 | H8: Discount | K8: 7 | L8: Manager | Q8: TotalAmount | R8: Pincode | S8: Discount | T8: EstablishedYear
A9: 8 | B9: DiscountApplied | D9: 8 | E9: Gender | G9: 8 | H9: StockQty | K9: 8 | L9: EstablishedYear | Q9: DiscountApplied | R9: Gender | S9: StockQty | T9: Employees
A10: 9 | B10: PaymentMode | D10: 9 | E10: DateOfBirth | G10: 9 | H10: WarrantyMonths | K10: 9 | L10: Employees | Q10: PaymentMode | R10: DateOfBirth | S10: WarrantyMonths | T10: MonthlyFootfall
A11: 10 | B11: OrderStatus | D11: 10 | E11: CustomerSince | G11: 10 | H11: MadeIn | K11: 10 | L11: MonthlyFootfall | Q11: OrderStatus | R11: CustomerSince | S11: MadeIn | T11: StoreRating
A12: 11 | B12: DeliveryDate | D12: 11 | E12: PreferredCategory | G12: 11 | H12: IsAvailable | K12: 11 | L12: StoreRating | Q12: DeliveryDate | R12: PreferredCategory | S12: IsAvailable | T12: OnlineEnabled
A13: 12 | B13: IsGift | D13: 12 | E13: LoyaltyPoints | G13: 12 | H13: Rating | K13: 12 | L13: OnlineEnabled | Q13: IsGift | R13: LoyaltyPoints | S13: Rating | T13: AreaSqFt
A14: 13 | B14: ShippingCharges | D14: 13 | E14: MaritalStatus | G14: 13 | H14: LaunchDate | K14: 13 | L14: AreaSqFt | Q14: ShippingCharges | R14: MaritalStatus | S14: LaunchDate | T14: StoreType
... A16: 15 | B16: ReviewGiven | D16: 15 | E16: AnnualIncome | G16: 15 | H16: HSNCode | K16: 15 | L16: ContactNumber | Q16: ReviewGiven | R16: AnnualIncome | S16: HSNCode | T16: Email
G17: 16 | H17: Store ID | K17: 16 | L17: Email

Sheet All Combined Data
A1: {=orders[#All]} -> OrderID | B1: CustomerID | C1: ProductID | D1: OrderDate | E1: Quantity | F1: UnitPrice | G1: TotalAmount | H1: DiscountApplied | I1: PaymentMode | J1: OrderStatus | K1: DeliveryDate | L1: IsGift | M1: ShippingCharges | N1: CouponUsed | O1: ReviewGiven | P1: {=customers[#Headers]} -> CustomerID | Q1: CustomerName | R1: Email | S1: Phone | T1: City | U1: State | V1: Pincode | W1: Gender | X1: DateOfBirth | Y1: CustomerSince | Z1: PreferredCategory | AA1: LoyaltyPoints | AB1: MaritalStatus | AC1: Occupation | AD1: AnnualIncome | AE1: {=Products[#Headers]} -> ProductID | AF1: ProductName | AG1: Category | AH1: SubCategory | AI1: Brand | AJ1: Price | AK1: Discount | AL1: StockQty | AM1: WarrantyMonths | AN1: MadeIn | AO1: IsAvailable | AP1: Rating | AQ1: LaunchDate | AR1: Returnable | AS1: HSNCode | AT1: Store ID | AU1: {=stores[#Headers]} -> New StoreID | AV1: StoreID | AW1: StoreName | AX1: City | AY1: State | AZ1: Pincode | BA1: Manager | BB1: EstablishedYear | BC1: Employees | BD1: MonthlyFootfall | BE1: StoreRating | BF1: OnlineEnabled | BG1: AreaSqFt | BH1: StoreType | BI1: ContactNumber | BJ1: Email
A2: O1001 | B2: C085 | C2: P180 | D2: 45687 | E2: 5 | F2: 31647 | G2: 94941 | H2: 0.14 | I2: Cash on Delivery | J2: Delivered | K2: 45859 | L2: Yes | M2: 41 | N2: Yes | O2: No | P2: =B2 -> C085 | Q2: =VLOOKUP($B2,customers[],MATCH(Q$1,customers[#Headers],0),0) -> Urishilla Yogi | R2: =VLOOKUP($B2,customers[],MATCH(R$1,customers[#Headers],0),0) -> yugbumb@example.net | S2: =VLOOKUP($B2,customers[],MATCH(S$1,customers[#Headers],0),0) -> 8519108839 | T2: =VLOOKUP($B2,customers[],MATCH(T$1,customers[#Headers],0),0) -> Jaipur | U2: =VLOOKUP($B2,customers[],MATCH(U$1,customers[#Headers],0),0) -> Rajasthan | V2: =VLOOKUP($B2,customers[],MATCH(V$1,customers[#Headers],0),0) -> 258713 | W2: =VLOOKUP($B2,customers[],MATCH(W$1,customers[#Headers],0),0) -> Female | X2: =VLOOKUP($B2,customers[],MATCH(X$1,customers[#Headers],0),0) -> 36242 | ... AD2: =VLOOKUP($B2,customers[],MATCH(AD$1,customers[#Headers],0),0) -> 309231 | AE2: =C2 -> P180 | AF2: =VLOOKUP($AE2,Products[],MATCH(AF$1,Products[#Headers],0),0) -> Accusamus TV | AG2: =VLOOKUP($AE2,Products[],MATCH(AG$1,Products[#Headers],0),0) -> Grocery | AH2: =VLOOKUP($AE2,Products[],MATCH(AH$1,Products[#Headers],0),0) -> Cotton | AI2: =VLOOKUP($AE2,Products[],MATCH(AI$1,Products[#Headers],0),0) -> Oza, Dara and Sami | AJ2: =VLOOKUP($AE2,Products[],MATCH(AJ$1,Products[#Headers],0),0) -> 31647 | AK2: =VLOOKUP($AE2,Products[],MATCH(AK$1,Products[#Headers],0),0) -> 14 | AL2: =VLOOKUP($AE2,Products[],MATCH(AL$1,Products[#Headers],0),0) -> 124 | AM2: =VLOOKUP($AE2,Products[],MATCH(AM$1,Products[#Headers],0),0) -> 6 | ... AT2: =VLOOKUP($AE2,Products[],MATCH(AT$1,Products[#Headers],0),0) -> 161 | AU2: =AT2 -> 161 | AV2: =IFERROR(VLOOKUP($AU2,stores[],MATCH(AV$1,stores[#Headers],0),0),"") | AW2: =IFERROR(VLOOKUP($AU2,stores[],MATCH(AW$1,stores[#Headers],0),0),"") | AX2: =IFERROR(VLOOKUP($AU2,stores[],MATCH(AX$1,stores[#Headers],0),0),"") | AY2: =IFERROR(VLOOKUP($AU2,stores[],MATCH(AY$1,stores[#Headers],0),0),"") | AZ2: =IFERROR(VLOOKUP($AU2,stores[],MATCH(AZ$1,stores[#Headers],0),0),"") | BA2: =IFERROR(VLOOKUP($AU2,stores[],MATCH(BA$1,stores[#Headers],0),0),"") | BB2: =IFERROR(VLOOKUP($AU2,stores[],MATCH(BB$1,stores[#Headers],0),0),"") | BC2: =IFERROR(VLOOKUP($AU2,stores[],MATCH(BC$1,stores[#Headers],0),0),"") | ... BJ2: =IFERROR(VLOOKUP($AU2,stores[],MATCH(BJ$1,stores[#Headers],0),0),"")
A3: O1002 | B3: C084 | C3: P127 | D3: 45802 | E3: 5 | F3: 24100 | G3: 96400 | H3: 0.1 | I3: Cash on Delivery | J3: Delivered | K3: 45858 | L3: No | M3: 455 | N3: No | O3: No | P3: =B3 -> C084 | Q3: =VLOOKUP($B3,customers[],MATCH(Q$1,customers[#Headers],0),0) -> Amara Narayan | R3: =VLOOKUP($B3,customers[],MATCH(R$1,customers[#Headers],0),0) -> advay45@example.net | S3: =VLOOKUP($B3,customers[],MATCH(S$1,customers[#Headers],0),0) -> 910174268414 | T3: =VLOOKUP($B3,customers[],MATCH(T$1,customers[#Headers],0),0) -> Kolkata | U3: =VLOOKUP($B3,customers[],MATCH(U$1,customers[#Headers],0),0) -> West Bengal | V3: =VLOOKUP($B3,customers[],MATCH(V$1,customers[#Headers],0),0) -> 933272 | W3: =VLOOKUP($B3,customers[],MATCH(W$1,customers[#Headers],0),0) -> Male | X3: =VLOOKUP($B3,customers[],MATCH(X$1,customers[#Headers],0),0) -> 33056 | ... AD3: =VLOOKUP($B3,customers[],MATCH(AD$1,customers[#Headers],0),0) -> 783546 | AE3: =C3 -> P127 | AF3: =VLOOKUP($AE3,Products[],MATCH(AF$1,Products[#Headers],0),0) -> Odio Rice | AG3: =VLOOKUP($AE3,Products[],MATCH(AG$1,Products[#Headers],0),0) -> Grocery | AH3: =VLOOKUP($AE3,Products[],MATCH(AH$1,Products[#Headers],0),0) -> Notebook | AI3: =VLOOKUP($AE3,Products[],MATCH(AI$1,Products[#Headers],0),0) -> Bhavsar-Mital | AJ3: =VLOOKUP($AE3,Products[],MATCH(AJ$1,Products[#Headers],0),0) -> 24100 | AK3: =VLOOKUP($AE3,Products[],MATCH(AK$1,Products[#Headers],0),0) -> 10 | AL3: =VLOOKUP($AE3,Products[],MATCH(AL$1,Products[#Headers],0),0) -> 179 | AM3: =VLOOKUP($AE3,Products[],MATCH(AM$1,Products[#Headers],0),0) -> 6 | ... AT3: =VLOOKUP($AE3,Products[],MATCH(AT$1,Products[#Headers],0),0) -> 44 | AU3: =AT3 -> 44 | AV3: =IFERROR(VLOOKUP($AU3,stores[],MATCH(AV$1,stores[#Headers],0),0),"") -> S044 | AW3: =IFERROR(VLOOKUP($AU3,stores[],MATCH(AW$1,stores[#Headers],0),0),"") -> Edwin Ltd Mart | AX3: =IFERROR(VLOOKUP($AU3,stores[],MATCH(AX$1,stores[#Headers],0),0),"") -> Pune | AY3: =IFERROR(VLOOKUP($AU3,stores[],MATCH(AY$1,stores[#Headers],0),0),"") -> Maharashtra | AZ3: =IFERROR(VLOOKUP($AU3,stores[],MATCH(AZ$1,stores[#Headers],0),0),"") -> 30299 | BA3: =IFERROR(VLOOKUP($AU3,stores[],MATCH(BA$1,stores[#Headers],0),0),"") -> Krish Vala | BB3: =IFERROR(VLOOKUP($AU3,stores[],MATCH(BB$1,stores[#Headers],0),0),"") -> 2021 | BC3: =IFERROR(VLOOKUP($AU3,stores[],MATCH(BC$1,stores[#Headers],0),0),"") -> 11 | ... BJ3: =IFERROR(VLOOKUP($AU3,stores[],MATCH(BJ$1,stores[#Headers],0),0),"") -> manderfrederick@sen.info
A4: O1003 | B4: C062 | C4: P132 | D4: 45697 | E4: 4 | F4: 89335 | G4: 268005 | H4: 0.29 | I4: Net Banking | J4: Delivered | K4: 45862 | L4: Yes | M4: 80 | N4: No | O4: No | P4: =B4 -> C062 | Q4: =VLOOKUP($B4,customers[],MATCH(Q$1,customers[#Headers],0),0) -> Udarsh Bala | R4: =VLOOKUP($B4,customers[],MATCH(R$1,customers[#Headers],0),0) -> hardik52@example.org | S4: =VLOOKUP($B4,customers[],MATCH(S$1,customers[#Headers],0),0) -> 914727790104 | T4: =VLOOKUP($B4,customers[],MATCH(T$1,customers[#Headers],0),0) -> Kolkata | U4: =VLOOKUP($B4,customers[],MATCH(U$1,customers[#Headers],0),0) -> West Bengal | V4: =VLOOKUP($B4,customers[],MATCH(V$1,customers[#Headers],0),0) -> 289861 | W4: =VLOOKUP($B4,customers[],MATCH(W$1,customers[#Headers],0),0) -> Female | X4: =VLOOKUP($B4,customers[],MATCH(X$1,customers[#Headers],0),0) -> 28908 | ... AD4: =VLOOKUP($B4,customers[],MATCH(AD$1,customers[#Headers],0),0) -> 884055 | AE4: =C4 -> P132 | AF4: =VLOOKUP($AE4,Products[],MATCH(AF$1,Products[#Headers],0),0) -> Ea Rice | AG4: =VLOOKUP($AE4,Products[],MATCH(AG$1,Products[#Headers],0),0) -> Home Appliance | AH4: =VLOOKUP($AE4,Products[],MATCH(AH$1,Products[#Headers],0),0) -> Cotton | AI4: =VLOOKUP($AE4,Products[],MATCH(AI$1,Products[#Headers],0),0) -> Sankaran, Randhawa and Balakrishnan | AJ4: =VLOOKUP($AE4,Products[],MATCH(AJ$1,Products[#Headers],0),0) -> 89335 | AK4: =VLOOKUP($AE4,Products[],MATCH(AK$1,Products[#Headers],0),0) -> 29 | AL4: =VLOOKUP($AE4,Products[],MATCH(AL$1,Products[#Headers],0),0) -> 738 | AM4: =VLOOKUP($AE4,Products[],MATCH(AM$1,Products[#Headers],0),0) -> 12 | ... AT4: =VLOOKUP($AE4,Products[],MATCH(AT$1,Products[#Headers],0),0) -> 163 | AU4: =AT4 -> 163 | AV4: =IFERROR(VLOOKUP($AU4,stores[],MATCH(AV$1,stores[#Headers],0),0),"") | AW4: =IFERROR(VLOOKUP($AU4,stores[],MATCH(AW$1,stores[#Headers],0),0),"") | AX4: =IFERROR(VLOOKUP($AU4,stores[],MATCH(AX$1,stores[#Headers],0),0),"") | AY4: =IFERROR(VLOOKUP($AU4,stores[],MATCH(AY$1,stores[#Headers],0),0),"") | AZ4: =IFERROR(VLOOKUP($AU4,stores[],MATCH(AZ$1,stores[#Headers],0),0),"") | BA4: =IFERROR(VLOOKUP($AU4,stores[],MATCH(BA$1,stores[#Headers],0),0),"") | BB4: =IFERROR(VLOOKUP($AU4,stores[],MATCH(BB$1,stores[#Headers],0),0),"") | BC4: =IFERROR(VLOOKUP($AU4,stores[],MATCH(BC$1,stores[#Headers],0),0),"") | ... BJ4: =IFERROR(VLOOKUP($AU4,stores[],MATCH(BJ$1,stores[#Headers],0),0),"")
A5: O1004 | B5: C062 | C5: P160 | D5: 45640 | E5: 2 | F5: 90888 | G5: 272664 | H5: 0.16 | I5: Cash on Delivery | J5: Shipped | K5: 45869 | L5: No | M5: 441 | N5: No | O5: No | P5: =B5 -> C062 | Q5: =VLOOKUP($B5,customers[],MATCH(Q$1,customers[#Headers],0),0) -> Udarsh Bala | R5: =VLOOKUP($B5,customers[],MATCH(R$1,customers[#Headers],0),0) -> hardik52@example.org | S5: =VLOOKUP($B5,customers[],MATCH(S$1,customers[#Headers],0),0) -> 914727790104 | T5: =VLOOKUP($B5,customers[],MATCH(T$1,customers[#Headers],0),0) -> Kolkata | U5: =VLOOKUP($B5,customers[],MATCH(U$1,customers[#Headers],0),0) -> West Bengal | V5: =VLOOKUP($B5,customers[],MATCH(V$1,customers[#Headers],0),0) -> 289861 | W5: =VLOOKUP($B5,customers[],MATCH(W$1,customers[#Headers],0),0) -> Female | X5: =VLOOKUP($B5,customers[],MATCH(X$1,customers[#Headers],0),0) -> 28908 | ... AD5: =VLOOKUP($B5,customers[],MATCH(AD$1,customers[#Headers],0),0) -> 884055 | AE5: =C5 -> P160 | AF5: =VLOOKUP($AE5,Products[],MATCH(AF$1,Products[#Headers],0),0) -> Voluptatibus Rice | AG5: =VLOOKUP($AE5,Products[],MATCH(AG$1,Products[#Headers],0),0) -> Home Appliance | AH5: =VLOOKUP($AE5,Products[],MATCH(AH$1,Products[#Headers],0),0) -> Android | AI5: =VLOOKUP($AE5,Products[],MATCH(AI$1,Products[#Headers],0),0) -> Mann-Loke | AJ5: =VLOOKUP($AE5,Products[],MATCH(AJ$1,Products[#Headers],0),0) -> 90888 | AK5: =VLOOKUP($AE5,Products[],MATCH(AK$1,Products[#Headers],0),0) -> 16 | AL5: =VLOOKUP($AE5,Products[],MATCH(AL$1,Products[#Headers],0),0) -> 90 | AM5: =VLOOKUP($AE5,Products[],MATCH(AM$1,Products[#Headers],0),0) -> 36 | ... AT5: =VLOOKUP($AE5,Products[],MATCH(AT$1,Products[#Headers],0),0) -> 34 | AU5: =AT5 -> 34 | AV5: =IFERROR(VLOOKUP($AU5,stores[],MATCH(AV$1,stores[#Headers],0),0),"") -> S034 | AW5: =IFERROR(VLOOKUP($AU5,stores[],MATCH(AW$1,stores[#Headers],0),0),"") -> Naidu PLC Mart | AX5: =IFERROR(VLOOKUP($AU5,stores[],MATCH(AX$1,stores[#Headers],0),0),"") -> Jaipur | AY5: =IFERROR(VLOOKUP($AU5,stores[],MATCH(AY$1,stores[#Headers],0),0),"") -> Rajasthan | AZ5: =IFERROR(VLOOKUP($AU5,stores[],MATCH(AZ$1,stores[#Headers],0),0),"") -> 947985 | BA5: =IFERROR(VLOOKUP($AU5,stores[],MATCH(BA$1,stores[#Headers],0),0),"") -> Eesha Vora | BB5: =IFERROR(VLOOKUP($AU5,stores[],MATCH(BB$1,stores[#Headers],0),0),"") -> 2018 | BC5: =IFERROR(VLOOKUP($AU5,stores[],MATCH(BC$1,stores[#Headers],0),0),"") -> 86 | ... BJ5: =IFERROR(VLOOKUP($AU5,stores[],MATCH(BJ$1,stores[#Headers],0),0),"") -> timothy35@patel-memon.com
A6: O1005 | B6: C052 | C6: P117 | D6: 45735 | E6: 3 | F6: 72884 | G6: 364420 | H6: 0.18 | I6: Cash on Delivery | J6: Delivered | K6: 45856 | L6: No | M6: 123 | N6: No | O6: Yes | P6: =B6 -> C052 | Q6: =VLOOKUP($B6,customers[],MATCH(Q$1,customers[#Headers],0),0) -> Vedika Sathe | R6: =VLOOKUP($B6,customers[],MATCH(R$1,customers[#Headers],0),0) -> nmahajan@example.net | S6: =VLOOKUP($B6,customers[],MATCH(S$1,customers[#Headers],0),0) -> 915614978403 | T6: =VLOOKUP($B6,customers[],MATCH(T$1,customers[#Headers],0),0) -> Kolkata | U6: =VLOOKUP($B6,customers[],MATCH(U$1,customers[#Headers],0),0) -> West Bengal | V6: =VLOOKUP($B6,customers[],MATCH(V$1,customers[#Headers],0),0) -> 900343 | W6: =VLOOKUP($B6,customers[],MATCH(W$1,customers[#Headers],0),0) -> Male | X6: =VLOOKUP($B6,customers[],MATCH(X$1,customers[#Headers],0),0) -> 25158 | ... AD6: =VLOOKUP($B6,customers[],MATCH(AD$1,customers[#Headers],0),0) -> 941717 | AE6: =C6 -> P117 | AF6: =VLOOKUP($AE6,Products[],MATCH(AF$1,Products[#Headers],0),0) -> Quidem Rice | AG6: =VLOOKUP($AE6,Products[],MATCH(AG$1,Products[#Headers],0),0) -> Fashion | AH6: =VLOOKUP($AE6,Products[],MATCH(AH$1,Products[#Headers],0),0) -> LED | AI6: =VLOOKUP($AE6,Products[],MATCH(AI$1,Products[#Headers],0),0) -> Chada, Chopra and Kothari | AJ6: =VLOOKUP($AE6,Products[],MATCH(AJ$1,Products[#Headers],0),0) -> 72884 | AK6: =VLOOKUP($AE6,Products[],MATCH(AK$1,Products[#Headers],0),0) -> 18 | AL6: =VLOOKUP($AE6,Products[],MATCH(AL$1,Products[#Headers],0),0) -> 95 | AM6: =VLOOKUP($AE6,Products[],MATCH(AM$1,Products[#Headers],0),0) -> 12 | ... AT6: =VLOOKUP($AE6,Products[],MATCH(AT$1,Products[#Headers],0),0) -> 185 | AU6: =AT6 -> 185 | AV6: =IFERROR(VLOOKUP($AU6,stores[],MATCH(AV$1,stores[#Headers],0),0),"") | AW6: =IFERROR(VLOOKUP($AU6,stores[],MATCH(AW$1,stores[#Headers],0),0),"") | AX6: =IFERROR(VLOOKUP($AU6,stores[],MATCH(AX$1,stores[#Headers],0),0),"") | AY6: =IFERROR(VLOOKUP($AU6,stores[],MATCH(AY$1,stores[#Headers],0),0),"") | AZ6: =IFERROR(VLOOKUP($AU6,stores[],MATCH(AZ$1,stores[#Headers],0),0),"") | BA6: =IFERROR(VLOOKUP($AU6,stores[],MATCH(BA$1,stores[#Headers],0),0),"") | BB6: =IFERROR(VLOOKUP($AU6,stores[],MATCH(BB$1,stores[#Headers],0),0),"") | BC6: =IFERROR(VLOOKUP($AU6,stores[],MATCH(BC$1,stores[#Headers],0),0),"") | ... BJ6: =IFERROR(VLOOKUP($AU6,stores[],MATCH(BJ$1,stores[#Headers],0),0),"")
A7: O1006 | B7: C035 | C7: P158 | D7: 45609 | E7: 2 | F7: 92731 | G7: 185462 | H7: 0.12 | I7: Credit Card | J7: Delivered | K7: 45865 | L7: No | M7: 484 | N7: No | O7: No | P7: =B7 -> C035 | Q7: =VLOOKUP($B7,customers[],MATCH(Q$1,customers[#Headers],0),0) -> Raksha Sundaram | R7: =VLOOKUP($B7,customers[],MATCH(R$1,customers[#Headers],0),0) -> balakrishnanwriddhish@example.net | S7: =VLOOKUP($B7,customers[],MATCH(S$1,customers[#Headers],0),0) -> 914808613171 | T7: =VLOOKUP($B7,customers[],MATCH(T$1,customers[#Headers],0),0) -> Ahmedabad | U7: =VLOOKUP($B7,customers[],MATCH(U$1,customers[#Headers],0),0) -> Gujarat | V7: =VLOOKUP($B7,customers[],MATCH(V$1,customers[#Headers],0),0) -> 748467 | W7: =VLOOKUP($B7,customers[],MATCH(W$1,customers[#Headers],0),0) -> Male | X7: =VLOOKUP($B7,customers[],MATCH(X$1,customers[#Headers],0),0) -> 33485 | ... AD7: =VLOOKUP($B7,customers[],MATCH(AD$1,customers[#Headers],0),0) -> 204520 | AE7: =C7 -> P158 | AF7: =VLOOKUP($AE7,Products[],MATCH(AF$1,Products[#Headers],0),0) -> Deserunt Washing Machine | AG7: =VLOOKUP($AE7,Products[],MATCH(AG$1,Products[#Headers],0),0) -> Home Appliance | AH7: =VLOOKUP($AE7,Products[],MATCH(AH$1,Products[#Headers],0),0) -> Organic | AI7: =VLOOKUP($AE7,Products[],MATCH(AI$1,Products[#Headers],0),0) -> Jhaveri Inc | AJ7: =VLOOKUP($AE7,Products[],MATCH(AJ$1,Products[#Headers],0),0) -> 92731 | AK7: =VLOOKUP($AE7,Products[],MATCH(AK$1,Products[#Headers],0),0) -> 12 | AL7: =VLOOKUP($AE7,Products[],MATCH(AL$1,Products[#Headers],0),0) -> 512 | AM7: =VLOOKUP($AE7,Products[],MATCH(AM$1,Products[#Headers],0),0) -> 24 | ... AT7: =VLOOKUP($AE7,Products[],MATCH(AT$1,Products[#Headers],0),0) -> 8 | AU7: =AT7 -> 8 | AV7: =IFERROR(VLOOKUP($AU7,stores[],MATCH(AV$1,stores[#Headers],0),0),"") -> S008 | AW7: =IFERROR(VLOOKUP($AU7,stores[],MATCH(AW$1,stores[#Headers],0),0),"") -> Palan LLC Mart | AX7: =IFERROR(VLOOKUP($AU7,stores[],MATCH(AX$1,stores[#Headers],0),0),"") -> Delhi | AY7: =IFERROR(VLOOKUP($AU7,stores[],MATCH(AY$1,stores[#Headers],0),0),"") -> Delhi | AZ7: =IFERROR(VLOOKUP($AU7,stores[],MATCH(AZ$1,stores[#Headers],0),0),"") -> 157043 | BA7: =IFERROR(VLOOKUP($AU7,stores[],MATCH(BA$1,stores[#Headers],0),0),"") -> Ekansh Palla | BB7: =IFERROR(VLOOKUP($AU7,stores[],MATCH(BB$1,stores[#Headers],0),0),"") -> 2018 | BC7: =IFERROR(VLOOKUP($AU7,stores[],MATCH(BC$1,stores[#Headers],0),0),"") -> 49 | ... BJ7: =IFERROR(VLOOKUP($AU7,stores[],MATCH(BJ$1,stores[#Headers],0),0),"") -> keya17@kar.com
A8: O1007 | B8: C032 | C8: P121 | D8: 45772 | E8: 3 | F8: 25227 | G8: 126135 | H8: 0.27 | I8: UPI | J8: Shipped | K8: 45860 | L8: Yes | M8: 255 | N8: No | O8: No | P8: =B8 -> C032 | Q8: =VLOOKUP($B8,customers[],MATCH(Q$1,customers[#Headers],0),0) -> Amaira Dhar | R8: =VLOOKUP($B8,customers[],MATCH(R$1,customers[#Headers],0),0) -> bhasinnoah@example.com | S8: =VLOOKUP($B8,customers[],MATCH(S$1,customers[#Headers],0),0) -> 9471746488 | T8: =VLOOKUP($B8,customers[],MATCH(T$1,customers[#Headers],0),0) -> Hyderabad | U8: =VLOOKUP($B8,customers[],MATCH(U$1,customers[#Headers],0),0) -> Telangana | V8: =VLOOKUP($B8,customers[],MATCH(V$1,customers[#Headers],0),0) -> 719065 | W8: =VLOOKUP($B8,customers[],MATCH(W$1,customers[#Headers],0),0) -> Female | X8: =VLOOKUP($B8,customers[],MATCH(X$1,customers[#Headers],0),0) -> 36753 | ... AD8: =VLOOKUP($B8,customers[],MATCH(AD$1,customers[#Headers],0),0) -> 1170201 | AE8: =C8 -> P121 | AF8: =VLOOKUP($AE8,Products[],MATCH(AF$1,Products[#Headers],0),0) -> Quas Washing Machine | AG8: =VLOOKUP($AE8,Products[],MATCH(AG$1,Products[#Headers],0),0) -> Grocery | AH8: =VLOOKUP($AE8,Products[],MATCH(AH$1,Products[#Headers],0),0) -> Cotton | AI8: =VLOOKUP($AE8,Products[],MATCH(AI$1,Products[#Headers],0),0) -> Kant, Sehgal and Prasad | AJ8: =VLOOKUP($AE8,Products[],MATCH(AJ$1,Products[#Headers],0),0) -> 25227 | AK8: =VLOOKUP($AE8,Products[],MATCH(AK$1,Products[#Headers],0),0) -> 27 | AL8: =VLOOKUP($AE8,Products[],MATCH(AL$1,Products[#Headers],0),0) -> 244 | AM8: =VLOOKUP($AE8,Products[],MATCH(AM$1,Products[#Headers],0),0) -> 36 | ... AT8: =VLOOKUP($AE8,Products[],MATCH(AT$1,Products[#Headers],0),0) -> 147 | AU8: =AT8 -> 147 | AV8: =IFERROR(VLOOKUP($AU8,stores[],MATCH(AV$1,stores[#Headers],0),0),"") | AW8: =IFERROR(VLOOKUP($AU8,stores[],MATCH(AW$1,stores[#Headers],0),0),"") | AX8: =IFERROR(VLOOKUP($AU8,stores[],MATCH(AX$1,stores[#Headers],0),0),"") | AY8: =IFERROR(VLOOKUP($AU8,stores[],MATCH(AY$1,stores[#Headers],0),0),"") | AZ8: =IFERROR(VLOOKUP($AU8,stores[],MATCH(AZ$1,stores[#Headers],0),0),"") | BA8: =IFERROR(VLOOKUP($AU8,stores[],MATCH(BA$1,stores[#Headers],0),0),"") | BB8: =IFERROR(VLOOKUP($AU8,stores[],MATCH(BB$1,stores[#Headers],0),0),"") | BC8: =IFERROR(VLOOKUP($AU8,stores[],MATCH(BC$1,stores[#Headers],0),0),"") | ... BJ8: =IFERROR(VLOOKUP($AU8,stores[],MATCH(BJ$1,stores[#Headers],0),0),"")
A9: O1008 | B9: C040 | C9: P164 | D9: 45511 | E9: 1 | F9: 61962 | G9: 61962 | H9: 0.19 | I9: Net Banking | J9: Cancelled | K9: 45860 | L9: Yes | M9: 110 | N9: No | O9: Yes | P9: =B9 -> C040 | Q9: =VLOOKUP($B9,customers[],MATCH(Q$1,customers[#Headers],0),0) -> Aadhya Andra | R9: =VLOOKUP($B9,customers[],MATCH(R$1,customers[#Headers],0),0) -> rmani@example.net | S9: =VLOOKUP($B9,customers[],MATCH(S$1,customers[#Headers],0),0) -> 911759464743 | T9: =VLOOKUP($B9,customers[],MATCH(T$1,customers[#Headers],0),0) -> Lucknow | U9: =VLOOKUP($B9,customers[],MATCH(U$1,customers[#Headers],0),0) -> Uttar Pradesh | V9: =VLOOKUP($B9,customers[],MATCH(V$1,customers[#Headers],0),0) -> 713695 | W9: =VLOOKUP($B9,customers[],MATCH(W$1,customers[#Headers],0),0) -> Male | X9: =VLOOKUP($B9,customers[],MATCH(X$1,customers[#Headers],0),0) -> 36035 | ... AD9: =VLOOKUP($B9,customers[],MATCH(AD$1,customers[#Headers],0),0) -> 716351 | AE9: =C9 -> P164 | AF9: =VLOOKUP($AE9,Products[],MATCH(AF$1,Products[#Headers],0),0) -> Repellat Washing Machine | AG9: =VLOOKUP($AE9,Products[],MATCH(AG$1,Products[#Headers],0),0) -> Home Appliance | AH9: =VLOOKUP($AE9,Products[],MATCH(AH$1,Products[#Headers],0),0) -> LED | AI9: =VLOOKUP($AE9,Products[],MATCH(AI$1,Products[#Headers],0),0) -> Luthra, Sachdeva and Prashad | AJ9: =VLOOKUP($AE9,Products[],MATCH(AJ$1,Products[#Headers],0),0) -> 61962 | AK9: =VLOOKUP($AE9,Products[],MATCH(AK$1,Products[#Headers],0),0) -> 19 | AL9: =VLOOKUP($AE9,Products[],MATCH(AL$1,Products[#Headers],0),0) -> 646 | AM9: =VLOOKUP($AE9,Products[],MATCH(AM$1,Products[#Headers],0),0) -> 24 | ... AT9: =VLOOKUP($AE9,Products[],MATCH(AT$1,Products[#Headers],0),0) -> 26 | AU9: =AT9 -> 26 | AV9: =IFERROR(VLOOKUP($AU9,stores[],MATCH(AV$1,stores[#Headers],0),0),"") -> S026 | AW9: =IFERROR(VLOOKUP($AU9,stores[],MATCH(AW$1,stores[#Headers],0),0),"") -> Sarma, Golla and Raghavan Mart | AX9: =IFERROR(VLOOKUP($AU9,stores[],MATCH(AX$1,stores[#Headers],0),0),"") -> Hyderabad | AY9: =IFERROR(VLOOKUP($AU9,stores[],MATCH(AY$1,stores[#Headers],0),0),"") -> Telangana | AZ9: =IFERROR(VLOOKUP($AU9,stores[],MATCH(AZ$1,stores[#Headers],0),0),"") -> 902771 | BA9: =IFERROR(VLOOKUP($AU9,stores[],MATCH(BA$1,stores[#Headers],0),0),"") -> Ridhi Batra | BB9: =IFERROR(VLOOKUP($AU9,stores[],MATCH(BB$1,stores[#Headers],0),0),"") -> 2008 | BC9: =IFERROR(VLOOKUP($AU9,stores[],MATCH(BC$1,stores[#Headers],0),0),"") -> 87 | ... BJ9: =IFERROR(VLOOKUP($AU9,stores[],MATCH(BJ$1,stores[#Headers],0),0),"") -> santyuvraj@pal-rajan.com
A10: O1009 | B10: C007 | C10: P137 | D10: 45522 | E10: 4 | F10: 6443 | G10: 32215 | H10: 0.06 | I10: Net Banking | J10: Pending | K10: 45865 | L10: Yes | M10: 433 | N10: Yes | O10: No | P10: =B10 -> C007 | Q10: =VLOOKUP($B10,customers[],MATCH(Q$1,customers[#Headers],0),0) -> Frederick Sunder | R10: =VLOOKUP($B10,customers[],MATCH(R$1,customers[#Headers],0),0) -> waliajeremiah@example.org | S10: =VLOOKUP($B10,customers[],MATCH(S$1,customers[#Headers],0),0) -> 7824896383 | T10: =VLOOKUP($B10,customers[],MATCH(T$1,customers[#Headers],0),0) -> Jaipur | U10: =VLOOKUP($B10,customers[],MATCH(U$1,customers[#Headers],0),0) -> Rajasthan | V10: =VLOOKUP($B10,customers[],MATCH(V$1,customers[#Headers],0),0) -> 657871 | W10: =VLOOKUP($B10,customers[],MATCH(W$1,customers[#Headers],0),0) -> Male | X10: =VLOOKUP($B10,customers[],MATCH(X$1,customers[#Headers],0),0) -> 27909 | ... AD10: =VLOOKUP($B10,customers[],MATCH(AD$1,customers[#Headers],0),0) -> 296100 | AE10: =C10 -> P137 | AF10: =VLOOKUP($AE10,Products[],MATCH(AF$1,Products[#Headers],0),0) -> Velit TV | AG10: =VLOOKUP($AE10,Products[],MATCH(AG$1,Products[#Headers],0),0) -> Grocery | AH10: =VLOOKUP($AE10,Products[],MATCH(AH$1,Products[#Headers],0),0) -> Smart | AI10: =VLOOKUP($AE10,Products[],MATCH(AI$1,Products[#Headers],0),0) -> Wable-Munshi | AJ10: =VLOOKUP($AE10,Products[],MATCH(AJ$1,Products[#Headers],0),0) -> 6443 | AK10: =VLOOKUP($AE10,Products[],MATCH(AK$1,Products[#Headers],0),0) -> 6 | AL10: =VLOOKUP($AE10,Products[],MATCH(AL$1,Products[#Headers],0),0) -> 311 | AM10: =VLOOKUP($AE10,Products[],MATCH(AM$1,Products[#Headers],0),0) -> 36 | ... AT10: =VLOOKUP($AE10,Products[],MATCH(AT$1,Products[#Headers],0),0) -> 156 | AU10: =AT10 -> 156 | AV10: =IFERROR(VLOOKUP($AU10,stores[],MATCH(AV$1,stores[#Headers],0),0),"") | AW10: =IFERROR(VLOOKUP($AU10,stores[],MATCH(AW$1,stores[#Headers],0),0),"") | AX10: =IFERROR(VLOOKUP($AU10,stores[],MATCH(AX$1,stores[#Headers],0),0),"") | AY10: =IFERROR(VLOOKUP($AU10,stores[],MATCH(AY$1,stores[#Headers],0),0),"") | AZ10: =IFERROR(VLOOKUP($AU10,stores[],MATCH(AZ$1,stores[#Headers],0),0),"") | BA10: =IFERROR(VLOOKUP($AU10,stores[],MATCH(BA$1,stores[#Headers],0),0),"") | BB10: =IFERROR(VLOOKUP($AU10,stores[],MATCH(BB$1,stores[#Headers],0),0),"") | BC10: =IFERROR(VLOOKUP($AU10,stores[],MATCH(BC$1,stores[#Headers],0),0),"") | ... BJ10: =IFERROR(VLOOKUP($AU10,stores[],MATCH(BJ$1,stores[#Headers],0),0),"")
A11: O1010 | B11: C018 | C11: P134 | D11: 45534 | E11: 3 | F11: 63656 | G11: 254624 | H11: 0.3 | I11: UPI | J11: Delivered | K11: 45866 | L11: No | M11: 26 | N11: Yes | O11: No | P11: =B11 -> C018 | Q11: =VLOOKUP($B11,customers[],MATCH(Q$1,customers[#Headers],0),0) -> Owen Mitra | R11: =VLOOKUP($B11,customers[],MATCH(R$1,customers[#Headers],0),0) -> tacharya@example.com | S11: =VLOOKUP($B11,customers[],MATCH(S$1,customers[#Headers],0),0) -> 916995777387 | T11: =VLOOKUP($B11,customers[],MATCH(T$1,customers[#Headers],0),0) -> Mumbai | U11: =VLOOKUP($B11,customers[],MATCH(U$1,customers[#Headers],0),0) -> Maharashtra | V11: =VLOOKUP($B11,customers[],MATCH(V$1,customers[#Headers],0),0) -> 148951 | W11: =VLOOKUP($B11,customers[],MATCH(W$1,customers[#Headers],0),0) -> Female | X11: =VLOOKUP($B11,customers[],MATCH(X$1,customers[#Headers],0),0) -> 27585 | ... AD11: =VLOOKUP($B11,customers[],MATCH(AD$1,customers[#Headers],0),0) -> 531680 | AE11: =C11 -> P134 | AF11: =VLOOKUP($AE11,Products[],MATCH(AF$1,Products[#Headers],0),0) -> Voluptatibus Shirt | AG11: =VLOOKUP($AE11,Products[],MATCH(AG$1,Products[#Headers],0),0) -> Fashion | AH11: =VLOOKUP($AE11,Products[],MATCH(AH$1,Products[#Headers],0),0) -> Cotton | AI11: =VLOOKUP($AE11,Products[],MATCH(AI$1,Products[#Headers],0),0) -> Jha LLC | AJ11: =VLOOKUP($AE11,Products[],MATCH(AJ$1,Products[#Headers],0),0) -> 63656 | AK11: =VLOOKUP($AE11,Products[],MATCH(AK$1,Products[#Headers],0),0) -> 30 | AL11: =VLOOKUP($AE11,Products[],MATCH(AL$1,Products[#Headers],0),0) -> 302 | AM11: =VLOOKUP($AE11,Products[],MATCH(AM$1,Products[#Headers],0),0) -> 24 | ... AT11: =VLOOKUP($AE11,Products[],MATCH(AT$1,Products[#Headers],0),0) -> 195 | AU11: =AT11 -> 195 | AV11: =IFERROR(VLOOKUP($AU11,stores[],MATCH(AV$1,stores[#Headers],0),0),"") | AW11: =IFERROR(VLOOKUP($AU11,stores[],MATCH(AW$1,stores[#Headers],0),0),"") | AX11: =IFERROR(VLOOKUP($AU11,stores[],MATCH(AX$1,stores[#Headers],0),0),"") | AY11: =IFERROR(VLOOKUP($AU11,stores[],MATCH(AY$1,stores[#Headers],0),0),"") | AZ11: =IFERROR(VLOOKUP($AU11,stores[],MATCH(AZ$1,stores[#Headers],0),0),"") | BA11: =IFERROR(VLOOKUP($AU11,stores[],MATCH(BA$1,stores[#Headers],0),0),"") | BB11: =IFERROR(VLOOKUP($AU11,stores[],MATCH(BB$1,stores[#Headers],0),0),"") | BC11: =IFERROR(VLOOKUP($AU11,stores[],MATCH(BC$1,stores[#Headers],0),0),"") | ... BJ11: =IFERROR(VLOOKUP($AU11,stores[],MATCH(BJ$1,stores[#Headers],0),0),"")
A12: O1011 | B12: C071 | C12: P137 | D12: 45726 | E12: 1 | F12: 6443 | G12: 25772 | H12: 0.06 | I12: Cash on Delivery | J12: Cancelled | K12: 45869 | L12: No | M12: 422 | N12: Yes | O12: Yes | P12: =B12 -> C071 | Q12: =VLOOKUP($B12,customers[],MATCH(Q$1,customers[#Headers],0),0) -> Kai Sant | R12: =VLOOKUP($B12,customers[],MATCH(R$1,customers[#Headers],0),0) -> dashzarna@example.org | S12: =VLOOKUP($B12,customers[],MATCH(S$1,customers[#Headers],0),0) -> 2253584143 | T12: =VLOOKUP($B12,customers[],MATCH(T$1,customers[#Headers],0),0) -> Bangalore | U12: =VLOOKUP($B12,customers[],MATCH(U$1,customers[#Headers],0),0) -> Karnataka | V12: =VLOOKUP($B12,customers[],MATCH(V$1,customers[#Headers],0),0) -> 249818 | W12: =VLOOKUP($B12,customers[],MATCH(W$1,customers[#Headers],0),0) -> Female | X12: =VLOOKUP($B12,customers[],MATCH(X$1,customers[#Headers],0),0) -> 37679 | ... AD12: =VLOOKUP($B12,customers[],MATCH(AD$1,customers[#Headers],0),0) -> 1157269 | AE12: =C12 -> P137 | AF12: =VLOOKUP($AE12,Products[],MATCH(AF$1,Products[#Headers],0),0) -> Velit TV | AG12: =VLOOKUP($AE12,Products[],MATCH(AG$1,Products[#Headers],0),0) -> Grocery | AH12: =VLOOKUP($AE12,Products[],MATCH(AH$1,Products[#Headers],0),0) -> Smart | AI12: =VLOOKUP($AE12,Products[],MATCH(AI$1,Products[#Headers],0),0) -> Wable-Munshi | AJ12: =VLOOKUP($AE12,Products[],MATCH(AJ$1,Products[#Headers],0),0) -> 6443 | AK12: =VLOOKUP($AE12,Products[],MATCH(AK$1,Products[#Headers],0),0) -> 6 | AL12: =VLOOKUP($AE12,Products[],MATCH(AL$1,Products[#Headers],0),0) -> 311 | AM12: =VLOOKUP($AE12,Products[],MATCH(AM$1,Products[#Headers],0),0) -> 36 | ... AT12: =VLOOKUP($AE12,Products[],MATCH(AT$1,Products[#Headers],0),0) -> 156 | AU12: =AT12 -> 156 | AV12: =IFERROR(VLOOKUP($AU12,stores[],MATCH(AV$1,stores[#Headers],0),0),"") | AW12: =IFERROR(VLOOKUP($AU12,stores[],MATCH(AW$1,stores[#Headers],0),0),"") | AX12: =IFERROR(VLOOKUP($AU12,stores[],MATCH(AX$1,stores[#Headers],0),0),"") | AY12: =IFERROR(VLOOKUP($AU12,stores[],MATCH(AY$1,stores[#Headers],0),0),"") | AZ12: =IFERROR(VLOOKUP($AU12,stores[],MATCH(AZ$1,stores[#Headers],0),0),"") | BA12: =IFERROR(VLOOKUP($AU12,stores[],MATCH(BA$1,stores[#Headers],0),0),"") | BB12: =IFERROR(VLOOKUP($AU12,stores[],MATCH(BB$1,stores[#Headers],0),0),"") | BC12: =IFERROR(VLOOKUP($AU12,stores[],MATCH(BC$1,stores[#Headers],0),0),"") | ... BJ12: =IFERROR(VLOOKUP($AU12,stores[],MATCH(BJ$1,stores[#Headers],0),0),"")
A13: O1012 | B13: C013 | C13: P151 | D13: 45510 | E13: 3 | F13: 46390 | G13: 139170 | H13: 0.22 | I13: Cash on Delivery | J13: Pending | K13: 45862 | L13: Yes | M13: 101 | N13: No | O13: Yes | P13: =B13 -> C013 | Q13: =VLOOKUP($B13,customers[],MATCH(Q$1,customers[#Headers],0),0) -> Raksha Mittal | R13: =VLOOKUP($B13,customers[],MATCH(R$1,customers[#Headers],0),0) -> mistryhemang@example.org | S13: =VLOOKUP($B13,customers[],MATCH(S$1,customers[#Headers],0),0) -> 1182449353 | T13: =VLOOKUP($B13,customers[],MATCH(T$1,customers[#Headers],0),0) -> Kolkata | U13: =VLOOKUP($B13,customers[],MATCH(U$1,customers[#Headers],0),0) -> West Bengal | V13: =VLOOKUP($B13,customers[],MATCH(V$1,customers[#Headers],0),0) -> 874016 | W13: =VLOOKUP($B13,customers[],MATCH(W$1,customers[#Headers],0),0) -> Male | X13: =VLOOKUP($B13,customers[],MATCH(X$1,customers[#Headers],0),0) -> 28624 | ... AD13: =VLOOKUP($B13,customers[],MATCH(AD$1,customers[#Headers],0),0) -> 755493 | AE13: =C13 -> P151 | AF13: =VLOOKUP($AE13,Products[],MATCH(AF$1,Products[#Headers],0),0) -> Dolores Shirt | AG13: =VLOOKUP($AE13,Products[],MATCH(AG$1,Products[#Headers],0),0) -> Grocery | AH13: =VLOOKUP($AE13,Products[],MATCH(AH$1,Products[#Headers],0),0) -> LED | AI13: =VLOOKUP($AE13,Products[],MATCH(AI$1,Products[#Headers],0),0) -> Tandon-Vaidya | AJ13: =VLOOKUP($AE13,Products[],MATCH(AJ$1,Products[#Headers],0),0) -> 46390 | AK13: =VLOOKUP($AE13,Products[],MATCH(AK$1,Products[#Headers],0),0) -> 22 | AL13: =VLOOKUP($AE13,Products[],MATCH(AL$1,Products[#Headers],0),0) -> 376 | AM13: =VLOOKUP($AE13,Products[],MATCH(AM$1,Products[#Headers],0),0) -> 6 | ... AT13: =VLOOKUP($AE13,Products[],MATCH(AT$1,Products[#Headers],0),0) -> 117 | AU13: =AT13 -> 117 | AV13: =IFERROR(VLOOKUP($AU13,stores[],MATCH(AV$1,stores[#Headers],0),0),"") | AW13: =IFERROR(VLOOKUP($AU13,stores[],MATCH(AW$1,stores[#Headers],0),0),"") | AX13: =IFERROR(VLOOKUP($AU13,stores[],MATCH(AX$1,stores[#Headers],0),0),"") | AY13: =IFERROR(VLOOKUP($AU13,stores[],MATCH(AY$1,stores[#Headers],0),0),"") | AZ13: =IFERROR(VLOOKUP($AU13,stores[],MATCH(AZ$1,stores[#Headers],0),0),"") | BA13: =IFERROR(VLOOKUP($AU13,stores[],MATCH(BA$1,stores[#Headers],0),0),"") | BB13: =IFERROR(VLOOKUP($AU13,stores[],MATCH(BB$1,stores[#Headers],0),0),"") | BC13: =IFERROR(VLOOKUP($AU13,stores[],MATCH(BC$1,stores[#Headers],0),0),"") | ... BJ13: =IFERROR(VLOOKUP($AU13,stores[],MATCH(BJ$1,stores[#Headers],0),0),"")
... A101: O1100 | B101: C041 | C101: P158 | D101: 45518 | E101: 5 | F101: 92731 | G101: 92731 | H101: 0.12 | I101: UPI | J101: Delivered | K101: 45859 | L101: No | M101: 69 | N101: Yes | O101: No | P101: =B101 -> C041 | Q101: =VLOOKUP($B101,customers[],MATCH(Q$1,customers[#Headers],0),0) -> Anthony Randhawa | R101: =VLOOKUP($B101,customers[],MATCH(R$1,customers[#Headers],0),0) -> abhiram90@example.net | S101: =VLOOKUP($B101,customers[],MATCH(S$1,customers[#Headers],0),0) -> 7439533942 | T101: =VLOOKUP($B101,customers[],MATCH(T$1,customers[#Headers],0),0) -> Lucknow | U101: =VLOOKUP($B101,customers[],MATCH(U$1,customers[#Headers],0),0) -> Uttar Pradesh | V101: =VLOOKUP($B101,customers[],MATCH(V$1,customers[#Headers],0),0) -> 47095 | W101: =VLOOKUP($B101,customers[],MATCH(W$1,customers[#Headers],0),0) -> Male | X101: =VLOOKUP($B101,customers[],MATCH(X$1,customers[#Headers],0),0) -> 25014 | ... AD101: =VLOOKUP($B101,customers[],MATCH(AD$1,customers[#Headers],0),0) -> 628362 | AE101: =C101 -> P158 | AF101: =VLOOKUP($AE101,Products[],MATCH(AF$1,Products[#Headers],0),0) -> Deserunt Washing Machine | AG101: =VLOOKUP($AE101,Products[],MATCH(AG$1,Products[#Headers],0),0) -> Home Appliance | AH101: =VLOOKUP($AE101,Products[],MATCH(AH$1,Products[#Headers],0),0) -> Organic | AI101: =VLOOKUP($AE101,Products[],MATCH(AI$1,Products[#Headers],0),0) -> Jhaveri Inc | AJ101: =VLOOKUP($AE101,Products[],MATCH(AJ$1,Products[#Headers],0),0) -> 92731 | AK101: =VLOOKUP($AE101,Products[],MATCH(AK$1,Products[#Headers],0),0) -> 12 | AL101: =VLOOKUP($AE101,Products[],MATCH(AL$1,Products[#Headers],0),0) -> 512 | AM101: =VLOOKUP($AE101,Products[],MATCH(AM$1,Products[#Headers],0),0) -> 24 | ... AT101: =VLOOKUP($AE101,Products[],MATCH(AT$1,Products[#Headers],0),0) -> 8 | AU101: =AT101 -> 8 | AV101: =IFERROR(VLOOKUP($AU101,stores[],MATCH(AV$1,stores[#Headers],0),0),"") -> S008 | AW101: =IFERROR(VLOOKUP($AU101,stores[],MATCH(AW$1,stores[#Headers],0),0),"") -> Palan LLC Mart | AX101: =IFERROR(VLOOKUP($AU101,stores[],MATCH(AX$1,stores[#Headers],0),0),"") -> Delhi | AY101: =IFERROR(VLOOKUP($AU101,stores[],MATCH(AY$1,stores[#Headers],0),0),"") -> Delhi | AZ101: =IFERROR(VLOOKUP($AU101,stores[],MATCH(AZ$1,stores[#Headers],0),0),"") -> 157043 | BA101: =IFERROR(VLOOKUP($AU101,stores[],MATCH(BA$1,stores[#Headers],0),0),"") -> Ekansh Palla | BB101: =IFERROR(VLOOKUP($AU101,stores[],MATCH(BB$1,stores[#Headers],0),0),"") -> 2018 | BC101: =IFERROR(VLOOKUP($AU101,stores[],MATCH(BC$1,stores[#Headers],0),0),"") -> 49 | ... BJ101: =IFERROR(VLOOKUP($AU101,stores[],MATCH(BJ$1,stores[#Headers],0),0),"") -> keya17@kar.com

Sheet All Pivot Table
A3: Total Orders | B3: Avg DiscountApplied | C3: Average of ShippingCharges | D3: Total StockQty | E3: Total Reveune | F3: Total Profit | W3: Total Orders
A4: 100 | B4: 0.1839 | C4: 249.75 | D4: 45002 | E4: 16189582 | F4: -2694893.9 | W4: Total Customers
W5: Total Products
W6: Total Qty Sold
W7: Medium/Avg Unit price
W8: Avg Discount Applied
W9: Avg Shipping Charges
W10: Gender Ratio
B11: Column Labels | W11: Total Loyalty Points
B12: Bangalore | C12: Chennai | D12: Lucknow | E12: Hyderabad | F12: Ahmedabad | G12: Mumbai | H12: Pune | I12: Delhi | J12: Kolkata | K12: Jaipur | L12: Grand Total | W12: Total Stock
A13: Sum of Reveune | B13: 554765 | C13: 984489 | D13: 1038969 | E13: 1187489 | F13: 1299362 | G13: 1562489 | H13: 1965577 | I13: 2121333 | J13: 2431637 | K13: 3043472 | L13: 16189582 | W13: Avg Product Rating
W14: Active Stores
W15: Total Revenue
W16: Discounted Sales
W17: Total Profit
L22: Brand Name | M22: Total Revenue | O22: Rank | P22: Brand name | Q22: Revenue
A23: Row Labels | B23: Sum of Reveune | F23: Row Labels | G23: Sum of Reveune | L23: Loyal PLC | M23: 926040 | O23: 1 | P23: =L23 -> Loyal PLC | Q23: =M23 -> 926040
A24: Electronics | B24: 4612379 | F24: China | G24: 4307164 | L24: Kar-Yogi | M24: 790728 | O24: 2 | P24: =L24 -> Kar-Yogi | Q24: =M24 -> 790728
A25: Fashion | B25: 4442628 | F25: India | G25: 3359867 | L25: Dey Inc | M25: 741034 | O25: 3 | P25: =L25 -> Dey Inc | Q25: =M25 -> 741034
A26: Grocery | B26: 4100483 | F26: Japan | G26: 2886681 | L26: Jhaveri Inc | M26: 649117 | O26: 4 | P26: =L26 -> Jhaveri Inc | Q26: =M26 -> 649117
A27: Home Appliance | B27: 3034092 | F27: Vietnam | G27: 5635870 | L27: Gera, Mishra and Chad | M27: 637858 | O27: 5 | P27: =L27 -> Gera, Mishra and Chad | Q27: =M27 -> 637858
A28: Grand Total | B28: 16189582 | L28: Sastry PLC | M28: 500946 | O28: 6 | P28: =L28 -> Sastry PLC | Q28: =M28 -> 500946
L29: Deshmukh Group | M29: 491270 | O29: 7 | P29: =L29 -> Deshmukh Group | Q29: =M29 -> 491270
L30: Pall-Chahal | M30: 448608 | O30: 8 | P30: =L30 -> Pall-Chahal | Q30: =M30 -> 448608
L31: Sankaran, Randhawa and Balakrishnan | M31: 446675 | O31: 9 | P31: =L31 -> Sankaran, Randhawa and Balakrishnan | Q31: =M31 -> 446675
L32: Luthra, Sachdeva and Prashad | M32: 433734 | O32: 10 | P32: =L32 -> Luthra, Sachdeva and Prashad | Q32: =M32 -> 433734
B34: Column Labels
B35: Organic | C35: Smart | D35: LED | E35: Android | F35: Notebook | G35: Cotton
A36: Sum of Reveune | B36: 1773553 | C36: 2052131 | D36: 2055017 | E36: 2343455 | F36: 3239446 | G36: 4725980
B37: =B36/SUM($B$36:$G$36) -> 0.10954903 | C37: =C36/SUM($B$36:$G$36) -> 0.12675627 | D37: =D36/SUM($B$36:$G$36) -> 0.12693453 | E37: =E36/SUM($B$36:$G$36) -> 0.1447508 | F37: =F36/SUM($B$36:$G$36) -> 0.20009448 | G37: =G36/SUM($B$36:$G$36) -> 0.29191489
B39: Highest Sub-Category | D39: {=INDEX(B35:G35,0,COUNTA(B35:G35))} -> Cotton | F39: Lowest Sub-Category | H39: =B35 -> Organic
B40: Revenue | D40: =MAX(B36:G36) -> 4725980 | F40: Revenue | H40: =B36 -> 1773553
B41: Revenue % | D41: =MAX(B37:G37) -> 0.29191489 | F41: Revenue % | H41: =B37 -> 0.10954903
A46: Row Labels | B46: Sum of Reveune | H46: Row Labels | I46: Sum of Reveune
A47: 2024 | B47: 7628203 | H47: Karnataka | I47: 554765 | K47: =H47 -> Karnataka
A48: Qtr3 | B48: 4073460 | H48: Tamil Nadu | I48: 984489 | K48: =H48 -> Tamil Nadu
A49: Jul | B49: 636728 | H49: Uttar Pradesh | I49: 1038969 | K49: =H49 -> Uttar Pradesh
A50: Aug | B50: 2358853 | H50: Telangana | I50: 1187489 | K50: =H50 -> Telangana
A51: Sep | B51: 1077879 | H51: Gujarat | I51: 1299362 | K51: =H51 -> Gujarat
A52: Qtr4 | B52: 3554743 | H52: Delhi | I52: 2121333 | K52: =H52 -> Delhi
...

Sheet Dashboard
AB6: DYNAMIC INSIGHTS & OUTCOMES
AC9: ='All Pivot Table'!D39 -> Cotton | AD9: has contributed highest revenue | AG9: ='All Pivot Table'!D40 -> 4725980 | AH9: which is | AI9: ='All Pivot Table'!D41 -> 0.29191489 | AJ9: of overall Revenue
AC10: ='All Pivot Table'!H39 -> Organic | AD10: Performing Lowest | AF10: =TEXT('All Pivot Table'!H40,"#,##0.0,,\M") & " (" & ROUND('All Pivot Table'!H41,2)*100 & "%)" -> 1.8M (11%) | AG10: Amongst all Sub-Category
AC13: Top N Brand By Revenue | AG13: 3
AC15: ='All Pivot Table'!L22 -> Brand Name | AG15: ='All Pivot Table'!M22 -> Total Revenue
AC16: {=_xlfn._xlws.FILTER(_xlfn._xlws.FILTER('All Pivot Table'!O23:Q32,'All Pivot Table'!O23:O32<=Dashboard!AG13),{0,1,0})} -> Loyal PLC | AG16: {=_xlfn._xlws.FILTER(_xlfn._xlws.FILTER('All Pivot Table'!O23:Q32,'All Pivot Table'!O23:O32<=Dashboard!AG13),{0,0,1})} -> 926040
AC17: Kar-Yogi | AG17: 790728
AC18: Dey Inc | AG18: 741034

Sheet Final Data
A1: Missing | B1: =COUNTBLANK(Combined_data[OrderID]) -> 0 | C1: =COUNTBLANK(Combined_data[CustomerID]) -> 0 | D1: =COUNTBLANK(Combined_data[ProductID]) -> 0 | E1: =COUNTBLANK(Combined_data[OrderDate]) -> 0 | F1: =COUNTBLANK(Combined_data[Quantity]) -> 0 | G1: =COUNTBLANK(Combined_data[UnitPrice]) -> 0 | H1: =COUNTBLANK(Combined_data[TotalAmount]) -> 0 | I1: =COUNTBLANK(Combined_data[DiscountApplied]) -> 0 | J1: =COUNTBLANK(Combined_data[PaymentMode]) -> 0 | K1: =COUNTBLANK(Combined_data[OrderStatus]) -> 0 | L1: =COUNTBLANK(Combined_data[DeliveryDate]) -> 0 | M1: =COUNTBLANK(Combined_data[IsGift]) -> 0 | N1: =COUNTBLANK(Combined_data[ShippingCharges]) -> 0 | O1: =COUNTBLANK(Combined_data[CouponUsed]) -> 0 | P1: =COUNTBLANK(Combined_data[ReviewGiven]) -> 0 | Q1: =COUNTBLANK(Combined_data[CustomerID2]) -> 0 | R1: =COUNTBLANK(Combined_data[CustomerName]) -> 0 | S1: =COUNTBLANK(Combined_data[Email]) -> 0 | T1: =COUNTBLANK(Combined_data[Phone]) -> 0 | U1: =COUNTBLANK(Combined_data[City]) -> 0 | V1: =COUNTBLANK(Combined_data[State]) -> 0 | W1: =COUNTBLANK(Combined_data[Pincode]) -> 0 | X1: =COUNTBLANK(Combined_data[Gender]) -> 0 | Y1: =COUNTBLANK(Combined_data[DateOfBirth]) -> 0 | Z1: =COUNTBLANK(Combined_data[CustomerSince]) -> 0 | AA1: =COUNTBLANK(Combined_data[PreferredCategory]) -> 0 | AB1: =COUNTBLANK(Combined_data[LoyaltyPoints]) -> 0 | AC1: =COUNTBLANK(Combined_data[MaritalStatus]) -> 0 | AD1: =COUNTBLANK(Combined_data[Occupation]) -> 0 | AE1: =COUNTBLANK(Combined_data[AnnualIncome]) -> 0 | AF1: =COUNTBLANK(Combined_data[ProductID3]) -> 0 | AG1: =COUNTBLANK(Combined_data[ProductName]) -> 0 | AH1: =COUNTBLANK(Combined_data[Category]) -> 0 | AI1: =COUNTBLANK(Combined_data[SubCategory]) -> 0 | AJ1: =COUNTBLANK(Combined_data[Brand]) -> 0 | AK1: =COUNTBLANK(Combined_data[Price]) -> 0 | AL1: =COUNTBLANK(Combined_data[Discount]) -> 0 | AM1: =COUNTBLANK(Combined_data[StockQty]) -> 0 | AN1: =COUNTBLANK(Combined_data[WarrantyMonths]) -> 0 | AO1: =COUNTBLANK(Combined_data[MadeIn]) -> 0 | AP1: =COUNTBLANK(Combined_data[IsAvailable]) -> 0 | AQ1: =COUNTBLANK(Combined_data[Rating]) -> 0 | AR1: =COUNTBLANK(Combined_data[LaunchDate]) -> 0 | AS1: =COUNTBLANK(Combined_data[Returnable]) -> 0 | AT1: =COUNTBLANK(Combined_data[HSNCode]) -> 0 | AU1: =COUNTBLANK(Combined_data[Store ID]) -> 0 | AV1: =COUNTBLANK(Combined_data[New StoreID]) -> 0 | AW1: =COUNTBLANK(Combined_data[StoreID]) -> 45 | AX1: =COUNTBLANK(Combined_data[StoreName]) -> 45 | AY1: =COUNTBLANK(Combined_data[City4]) -> 45 | AZ1: =COUNTBLANK(Combined_data[State5]) -> 45 | BA1: =COUNTBLANK(Combined_data[Pincode6]) -> 45 | BB1: =COUNTBLANK(Combined_data[Manager]) -> 45 | BC1: =COUNTBLANK(Combined_data[EstablishedYear]) -> 45 | BD1: =COUNTBLANK(Combined_data[Employees]) -> 45 | BE1: =COUNTBLANK(Combined_data[MonthlyFootfall]) -> 45 | BF1: =COUNTBLANK(Combined_data[StoreRating]) -> 45 | BG1: =COUNTBLANK(Combined_data[OnlineEnabled]) -> 45 | BH1: =COUNTBLANK(Combined_data[AreaSqFt]) -> 45 | BI1: =COUNTBLANK(Combined_data[StoreType]) -> 45 | BJ1: =COUNTBLANK(Combined_data[ContactNumber]) -> 45 | BK1: =COUNTBLANK(Combined_data[Email7]) -> 45 | BL1: =COUNTBLANK(Combined_data[Reveune]) -> 0 | BM1: =COUNTBLANK(Combined_data[Final Amount]) -> 0 | BN1: =COUNTBLANK(Combined_data[Profit]) -> 0
